<mujoco model="planar_3dof">
  <option gravity="0 0 0"/>

  <worldbody>
    <body name="link1" pos="0 0 0">
      <joint name="j1" type="hinge" axis="0 0 1"/>
      <geom type="capsule" fromto="0 0 0 0.3 0 0" size="0.02"/>

      <body name="link2" pos="0.3 0 0">
        <joint name="j2" type="hinge" axis="0 0 1"/>
        <geom type="capsule" fromto="0 0 0 0.25 0 0" size="0.018"/>

        <body name="link3" pos="0.25 0 0">
          <joint name="j3" type="hinge" axis="0 0 1"/>
          <geom type="capsule" fromto="0 0 0 0.15 0 0" size="0.015"/>
          <site name="end_site" pos="0.15 0 0" size="0.01"/>
        </body>
      </body>
    </body>
  </worldbody>
</mujoco>
