<mujoco model="shared_pupper_leg">
  <default>
    <joint armature="0.01" damping="0.01" frictionloss="0.01" limited="true"/>
    <geom contype="0" conaffinity="0"/>
  </default>

  <asset>
    <mesh name="body" file="BodyV4v70_001.stl"/>
    <mesh name="hip_mesh" file="LegAssemblyForFlangedv26_010.stl" scale="1 -1 1"/>
    <mesh name="upper_leg_mesh" file="LegAssemblyForFlangedv26_011.stl" scale="1 1 -1"/>
    <mesh name="lower_leg_mesh" file="LegAssemblyForFlangedv26_012.stl" scale="1 1 -1"/>
  </asset>

  <worldbody>
    <light diffuse="1 1 1" pos="0 0 3" dir="0 0 -1"/>
    <camera name="side" pos="0 -1.0 0.58" xyaxes="1 0 0 0 0.22 1"/>
    <camera name="front" pos="1.2 -0.05 0.5" xyaxes="0 1 0 -0.2 0 1"/>

    <body name="base" pos="0 0 0.5" quat="0 0 0 1">
      <inertial pos="0 0 0" mass="1.506" diaginertia="0.0085 0.0085 0.0024"/>
      <geom quat="0.499998 -0.5 -0.500002 0.5" type="mesh" group="1" density="0" mesh="body"/>

      <body name="hip" pos="0.075 0.0835 0" quat="0.707105 -0.707108 0 0">
        <inertial pos="0 0 0" mass="0.18" diaginertia="7.4e-05 5.8e-05 4.8e-05"/>
        <joint name="HAA" axis="0 0 1" range="-2.51 1.22"/>
        <geom pos="0 0 -0.028" quat="1.32679e-06 0 0 1" type="mesh" group="1" density="0" mesh="hip_mesh"/>
        <geom type="cylinder" size="0.015 0.02" rgba="0.4 0.6 0.8 0.35"/>

        <body name="upper_leg" pos="0 0 0" quat="-3.89602e-06 0.707107 -1.29867e-06 -0.707107">
          <inertial pos="0 -0.0334 0.05419" quat="0.903877 0.427791 0 0" mass="0.186"
              diaginertia="0.000113 9.74951e-05 4.65049e-05"/>
          <joint name="HFE" axis="0 0 1" range="-3.14 0.42"/>
          <geom pos="0.028 0 0" quat="-2.93388e-06 0.707108 2.26082e-06 0.707106"
              type="mesh" group="1" density="0" mesh="upper_leg_mesh"/>
          <geom type="capsule" fromto="0 0 0 0 -0.0494 0.0685" size="0.012" rgba="0.6 0.6 0.8 0.35"/>

          <body name="lower_leg" pos="0 -0.0494 0.0685" quat="9.38184e-07 -0.707108 9.38187e-07 0.707105">
            <inertial pos="0.03866 0.03585 0.01833" quat="0.653281 0.270598 -0.653281 0.270598"
                mass="0.05" diaginertia="7.7e-05 7.55e-05 5.5e-06"/>
            <joint name="KFE" axis="0 0 1" range="-0.71 2.79"/>
            <geom pos="0.0685 -0.0494 -0.028" quat="1.76029e-12 1.32679e-06 1 1.32679e-06"
                type="mesh" group="1" density="0" mesh="lower_leg_mesh"/>
            <geom type="capsule" fromto="0 0 0 0.06231 0.06216 0.018" size="0.01" rgba="0.6 0.8 0.6 0.35"/>
            <geom type="sphere" size="0.01995" pos="0.06231 0.06216 0.018" rgba="0.8 0.3 0.3 1"/>
            <site name="foot" pos="0.06231 0.06216 0.018" size="0.015" rgba="1 0.2 0.2 1"/>
          </body>
        </body>
      </body>
    </body>
  </worldbody>

  <actuator>
    <general name="haa_motor" joint="HAA" forcerange="-3 3" forcelimited="true"
        biastype="affine" gainprm="1 0 0" biasprm="0 0 0"/>
    <general name="hfe_motor" joint="HFE" forcerange="-3 3" forcelimited="true"
        biastype="affine" gainprm="1 0 0" biasprm="0 0 0"/>
    <general name="kfe_motor" joint="KFE" forcerange="-3 3" forcelimited="true"
        biastype="affine" gainprm="1 0 0" biasprm="0 0 0"/>
  </actuator>
</mujoco>
